<mujoco model="ur5e">
    <compiler angle="degree" eulerseq="xyz"/>

    <asset>
        <mesh name="base" file=".\meshes\base.stl" />

        <mesh name="shoulder" file=".\meshes\shoulder.stl" />
        <mesh name="upperarm" file=".\meshes\upperarm.stl" />
        <mesh name="forearm" file=".\meshes\forearm.stl" />
        <mesh name="wrist1" file=".\meshes\wrist1.stl" />
        <mesh name="wrist2" file=".\meshes\wrist2.stl" />
        <mesh name="wrist3" file=".\meshes\wrist3.stl" />

        <texture name="texplane" type="2d" builtin="checker" rgb1="1 1 1" rgb2=".6 .6 .6" width="512" height="512"/>
        <material name='MatPlane' reflectance='0' texture="texplane" texrepeat="1 1" texuniform="true" rgba=".7 .7 .7 1"/>

        <mesh name="bladeVxl" file=".\meshes\1m bladeVoxelized 5mm 220905-200157.stl" scale="0.005 0.005 0.005"/>

    </asset>

    <actuator>
        <!-- Range of 402 degree ~ 7 radian -->
        <position ctrllimited="true" ctrlrange="-402 402" forcelimited="true" forcerange=" -4500 4500"
                  joint="shoulder_pan_joint" kp="10000"
                  name="ur5:joint1"/>
        <position ctrllimited="true" ctrlrange="-402 402" forcelimited="true" forcerange="-4500 4500"
                  joint="shoulder_lift_joint" kp="10000"
                  name="ur5:joint2"/>
        <position ctrllimited="true" ctrlrange="-402 402" forcelimited="true" forcerange="-4500 4500"
                  joint="elbow_joint" kp="10000"
                  name="ur5:joint3"/>
        <position ctrllimited="true" ctrlrange="-402 402" forcelimited="true" forcerange="-4500 4500"
                  joint="wrist_1_joint" kp="10000"
                  name="ur5:joint4"/>
        <position ctrllimited="true" ctrlrange="-402 402" forcelimited="true" forcerange="-4500 4500"
                  joint="wrist_2_joint" kp="10000"
                  name="ur5:joint5"/>
        <position ctrllimited="true" ctrlrange="-402 402" forcelimited="true" forcerange="-4500 4500"
                  joint="wrist_3_joint" kp="10000"
                  name="ur5:joint6"/>
    </actuator>
    
    <worldbody>
        <light directional="true" diffuse=".8 .8 .8" pos="0 0 10" dir="0 0 -10" castshadow="false"/>
        <site type="box" size="2 2 .00005" material="MatPlane"/>
        
        <camera pos="1.303 -0.888 1.128" xyaxes="0.735 0.679 0.000 -0.280 0.303 0.911"/>

        <!--
        <site name="workingRadius" type="sphere" pos="0 0 0" size=".88 .88 .88" rgba="0 0 1 .2"/>
        -->
        
        <body name="rotorblade2" pos="-.93 .9 -.15" euler = "0 0 -90"> 
            <geom type="mesh" rgba="1 1 0 1" mesh="bladeVxl" mass="2"/>
        </body> 
            
        <body name="base" pos="0 0 0" euler="0 0 0">
            <body name="base_link" pos="0 0 0">
                <site name="xax1" type="box" pos="0.15 0 0" size="0.15 0.005 0.005" rgba="1 0 0 1" euler="0 0 0"/>
                <site name="yax1" type="box" pos="0 0.15 0" size="0.005 0.15 0.005" rgba="0 1 0 1" euler="0 0 0"/>
                <site name="zax1" type="box" pos="0 0 0.15" size="0.005 0.005 0.15" rgba="0 0 1 1" euler="0 0 0"/>
                                        
                <geom type="mesh" rgba="1 .5 0 .5" mesh="base" />
                <geom rgba="1 0 0 1" size="0.01 0.01 0.01"  type="box"/>

                <body name="shoulder_link" pos="0 0 0.1625">
                     
                    <joint name="shoulder_pan_joint" axis="0 0 1" damping="1000" limited="true" range="-402 402"  />
                    <geom type="mesh" rgba="1 .5 0 .5" mesh="shoulder" euler="0 0 180"/>
                    <geom rgba="1 0 0 1" size="0.01 0.01 0.01"  type="box"/>
                    
                    <body name="upper_arm_link" euler="90 0 0">
                         
                        <joint name="shoulder_lift_joint"  axis="0 0 1" damping="1000" limited="true" range="-402 402" />
                        <geom type="mesh" rgba="1 .5 0 .5" mesh="upperarm" pos = "0 0 .138" euler="0 -90 -90"/>                        
                        <geom rgba="0 0 1 .1" size="0.01 0.01 0.01"  type="box"/>
                        
                        <body name="forearm_link" pos="-.425 0 0">
                             
                            <joint name="elbow_joint" axis="0 0 1" damping="1000" limited="true" range="-402 402" />
                            <geom type="mesh" rgba="1 .5 0 .5" mesh="forearm" pos = "0 0 .0" euler="0 -90 -90"/>
                            <geom rgba="1 0 0 1" size="0.01 0.01 0.01"  type="box"/>
                            
                            <body name="wrist_1_link" pos="-.3922 0 0">
                                 
                                <joint name="wrist_1_joint" axis="0 0 1" damping="1000" limited="true" range="-402 402" />
                                <geom type="mesh" rgba="1 .5 0 .5" mesh="wrist1"  pos = "0 0 0" euler="90 0 0"/>
                                <geom rgba="1 0 0 1" size="0.01 0.01 0.01"  type="box"/>
                                
                                <body name="wrist_2_link" pos="0 0 0.1333" euler="90 0 0">
                                     
                                    <joint name="wrist_2_joint" axis="0 0 1" damping="1000" limited="true" range="-402 402" />
                                    <geom type="mesh" rgba="1 .5 0 .5" mesh="wrist2" pos = "0 0 0" euler="0 0 0"/>
                                    <geom rgba="1 0 0 1" size="0.01 0.01 0.01"  type="box"/>
                                    
                                    <body name="wrist_3_link" pos="0 0 0.0997" euler="-90 0 0">
                                         
                                        <joint name="wrist_3_joint" pos="0 0 0" axis="0 0 1" damping="1000" limited="true" range="-402 402" />
                                        <geom type="mesh" rgba="1 .5 0 .5" mesh="wrist3" pos = "0 0 0" euler="90 0 0"/>
                                        <geom rgba="1 0 0 1" size="0.01 0.01 0.01"  type="box"/>
                             
                                        <geom name="tip" rgba="1 0 0 1" size="0.01 0.01 0.01" pos="0 0 0.0996" type="box" />
                                        <site name="xax" type="box" pos="0.15 0 0.0996" size="0.15 0.005 0.005" rgba="1 0 0 1" euler="0 0 0"/>
                                        <site name="yax" type="box" pos="0 0.15 0.0996" size="0.005 0.15 0.005" rgba="0 1 0 1" euler="0 0 0"/>
                                        <site name="zax" type="box" pos="0 0 0.2496" size="0.005 0.005 0.15" rgba="0 0 1 1" euler="0 0 0"/>

                                            <body name="ee_scanner" pos="0 0 0.1746">
                                                <!-- pos = 0,0996 + 0,075
                                                Micro Epsilon Scanner: SurfaceControl-3D 3510-80 
                                                Scanners Size: 220x150x49 mm
                                                Scanners mass: 1.9 kg

                                                Size Mesure is declared as "radian" and "1" equals 1 m -> 220mm = 0,11
                                                s_size_height = 49 # mm     -> 0.0245
                                                s_size_width = 220 # mm     -> 0.11
                                                s_size_length = 150 # mm    -> 0.075
                                                -->
                                                <geom type="box" size="0.11 0.0245 0.075" rgba="1 0 0 1"/>
                                                
                                                <!--
                                                Measurement Area: 80 mm x 50 mm at 130 mm Distance
                                                                  z size is actuall 0, but this ist no valid input, thus it is choosen a small positive value
                                                the distamce of the measurement area is calculated from the center of the scanner: 
                                                    + 0.075 to get to the exterior surface
                                                    + 0.13 working distance
                                                    = 0.205
                                                -->
                                                <site name="ee_scanner_measurementArea_min" type="box" pos="0 0 0.195" size="0.0675 0.046 0.005" rgba="0 1 1 .2"/>
                                                <site name="ee_scanner_measurementArea_mid" type="box" pos="0 0 0.205" size="0.08 0.05 0.005" rgba="0 1 1 .2"/>
                                                <site name="ee_scanner_measurementArea_max" type="box" pos="0 0 0.215" size="0.0775 0.052 0.005" rgba="0 1 1 .2"/>
                                            
                                            </body>

                                    </body>
                                </body>
                            </body>
                        </body>
                    </body>
                </body>
            </body>
        </body>

    </worldbody>
</mujoco>
